{
 "cells": [
  {
   "cell_type": "code",
   "execution_count": 1,
   "id": "34543675",
   "metadata": {},
   "outputs": [],
   "source": [
    "import tensorflow as tf\n",
    "from tensorflow.keras.datasets import mnist\n",
    "from tensorflow.keras.models import Sequential\n",
    "from tensorflow.keras.layers import Dense, Flatten, Conv2D, MaxPooling2D\n",
    "from tensorflow.keras.losses import SparseCategoricalCrossentropy\n",
    "from tensorflow.keras.optimizers import Adam"
   ]
  },
  {
   "cell_type": "code",
   "execution_count": 2,
   "id": "7db17e4c",
   "metadata": {},
   "outputs": [],
   "source": [
    "train_data = 'train/'\n",
    "test_data = 'test/'"
   ]
  },
  {
   "cell_type": "code",
   "execution_count": 3,
   "id": "10c16fae",
   "metadata": {},
   "outputs": [],
   "source": [
    "from tensorflow.keras.preprocessing.image import ImageDataGenerator\n",
    "\n",
    "train_data_gen = ImageDataGenerator(rescale = 1./255)\n",
    "test_data_gen = ImageDataGenerator(rescale = 1./255)"
   ]
  },
  {
   "cell_type": "code",
   "execution_count": 4,
   "id": "912603cb",
   "metadata": {},
   "outputs": [
    {
     "name": "stdout",
     "output_type": "stream",
     "text": [
      "Found 9246 images belonging to 2 classes.\n"
     ]
    }
   ],
   "source": [
    "train_ = train_data_gen.flow_from_directory(train_data,\n",
    "                                           target_size = (150, 150),\n",
    "                                           batch_size = 32,\n",
    "                                           class_mode = 'binary')"
   ]
  },
  {
   "cell_type": "code",
   "execution_count": 5,
   "id": "0a96a327",
   "metadata": {},
   "outputs": [
    {
     "name": "stdout",
     "output_type": "stream",
     "text": [
      "Found 506 images belonging to 2 classes.\n"
     ]
    }
   ],
   "source": [
    "test_ = test_data_gen.flow_from_directory(test_data,\n",
    "                                         target_size = (150, 150),\n",
    "                                         batch_size = 32,\n",
    "                                         class_mode = 'binary')"
   ]
  },
  {
   "cell_type": "code",
   "execution_count": 6,
   "id": "1d89096d",
   "metadata": {},
   "outputs": [
    {
     "name": "stderr",
     "output_type": "stream",
     "text": [
      "C:\\Users\\alpnn\\AppData\\Local\\anaconda3\\envs\\YoloV8\\Lib\\site-packages\\keras\\src\\layers\\convolutional\\base_conv.py:99: UserWarning: Do not pass an `input_shape`/`input_dim` argument to a layer. When using Sequential models, prefer using an `Input(shape)` object as the first layer in the model instead.\n",
      "  super().__init__(\n"
     ]
    }
   ],
   "source": [
    "model = Sequential([\n",
    "    Conv2D(32, (3, 3), activation='relu', input_shape=(150, 150, 3)),\n",
    "    MaxPooling2D((2, 2)),\n",
    "    Conv2D(64, (3, 3), activation='relu'),\n",
    "    MaxPooling2D((2, 2)),\n",
    "    Conv2D(128, (3, 3), activation='relu'),\n",
    "    MaxPooling2D((2, 2)),\n",
    "    Conv2D(64, (3, 3), activation='relu'),\n",
    "    MaxPooling2D((2, 2)),\n",
    "    Conv2D(64, (3, 3), activation = 'relu'),\n",
    "    MaxPooling2D(2, 2),\n",
    "    Flatten(),\n",
    "    Dense(512, activation='relu'),\n",
    "    Dense(1, activation='sigmoid')\n",
    "])"
   ]
  },
  {
   "cell_type": "code",
   "execution_count": 7,
   "id": "1b3606fd",
   "metadata": {},
   "outputs": [],
   "source": [
    "model.compile(optimizer = 'adam',\n",
    "             loss = 'binary_crossentropy',\n",
    "             metrics = ['accuracy'])"
   ]
  },
  {
   "cell_type": "code",
   "execution_count": 10,
   "id": "492eb2a3",
   "metadata": {},
   "outputs": [
    {
     "name": "stdout",
     "output_type": "stream",
     "text": [
      "Epoch 1/25\n",
      "\u001b[1m  6/100\u001b[0m \u001b[32m━\u001b[0m\u001b[37m━━━━━━━━━━━━━━━━━━━\u001b[0m \u001b[1m28s\u001b[0m 304ms/step - accuracy: 0.4846 - loss: 0.7231"
     ]
    },
    {
     "ename": "UnknownError",
     "evalue": "Graph execution error:\n\nDetected at node PyFunc defined at (most recent call last):\n<stack traces unavailable>\nOSError: image file is truncated (37 bytes not processed)\nTraceback (most recent call last):\n\n  File \"C:\\Users\\alpnn\\AppData\\Local\\anaconda3\\envs\\YoloV8\\Lib\\site-packages\\tensorflow\\python\\ops\\script_ops.py\", line 270, in __call__\n    ret = func(*args)\n          ^^^^^^^^^^^\n\n  File \"C:\\Users\\alpnn\\AppData\\Local\\anaconda3\\envs\\YoloV8\\Lib\\site-packages\\tensorflow\\python\\autograph\\impl\\api.py\", line 643, in wrapper\n    return func(*args, **kwargs)\n           ^^^^^^^^^^^^^^^^^^^^^\n\n  File \"C:\\Users\\alpnn\\AppData\\Local\\anaconda3\\envs\\YoloV8\\Lib\\site-packages\\tensorflow\\python\\data\\ops\\from_generator_op.py\", line 198, in generator_py_func\n    values = next(generator_state.get_iterator(iterator_id))\n             ^^^^^^^^^^^^^^^^^^^^^^^^^^^^^^^^^^^^^^^^^^^^^^^\n\n  File \"C:\\Users\\alpnn\\AppData\\Local\\anaconda3\\envs\\YoloV8\\Lib\\site-packages\\keras\\src\\trainers\\data_adapters\\py_dataset_adapter.py\", line 250, in _get_iterator\n    for i, batch in enumerate(gen_fn()):\n\n  File \"C:\\Users\\alpnn\\AppData\\Local\\anaconda3\\envs\\YoloV8\\Lib\\site-packages\\keras\\src\\trainers\\data_adapters\\py_dataset_adapter.py\", line 244, in generator_fn\n    yield self.py_dataset[i]\n          ~~~~~~~~~~~~~~~^^^\n\n  File \"C:\\Users\\alpnn\\AppData\\Local\\anaconda3\\envs\\YoloV8\\Lib\\site-packages\\keras\\src\\legacy\\preprocessing\\image.py\", line 68, in __getitem__\n    return self._get_batches_of_transformed_samples(index_array)\n           ^^^^^^^^^^^^^^^^^^^^^^^^^^^^^^^^^^^^^^^^^^^^^^^^^^^^^\n\n  File \"C:\\Users\\alpnn\\AppData\\Local\\anaconda3\\envs\\YoloV8\\Lib\\site-packages\\keras\\src\\legacy\\preprocessing\\image.py\", line 313, in _get_batches_of_transformed_samples\n    img = image_utils.load_img(\n          ^^^^^^^^^^^^^^^^^^^^^\n\n  File \"C:\\Users\\alpnn\\AppData\\Local\\anaconda3\\envs\\YoloV8\\Lib\\site-packages\\keras\\src\\utils\\image_utils.py\", line 292, in load_img\n    img = img.resize(width_height_tuple, resample)\n          ^^^^^^^^^^^^^^^^^^^^^^^^^^^^^^^^^^^^^^^^\n\n  File \"C:\\Users\\alpnn\\AppData\\Local\\anaconda3\\envs\\YoloV8\\Lib\\site-packages\\PIL\\Image.py\", line 2156, in resize\n    self.load()\n\n  File \"C:\\Users\\alpnn\\AppData\\Local\\anaconda3\\envs\\YoloV8\\Lib\\site-packages\\PIL\\ImageFile.py\", line 266, in load\n    raise OSError(msg)\n\nOSError: image file is truncated (37 bytes not processed)\n\n\n\t [[{{node PyFunc}}]]\n\t [[IteratorGetNext]] [Op:__inference_one_step_on_iterator_2588]",
     "output_type": "error",
     "traceback": [
      "\u001b[1;31m---------------------------------------------------------------------------\u001b[0m",
      "\u001b[1;31mUnknownError\u001b[0m                              Traceback (most recent call last)",
      "Cell \u001b[1;32mIn[10], line 1\u001b[0m\n\u001b[1;32m----> 1\u001b[0m egitim \u001b[38;5;241m=\u001b[39m model\u001b[38;5;241m.\u001b[39mfit(train_,\n\u001b[0;32m      2\u001b[0m                   steps_per_epoch \u001b[38;5;241m=\u001b[39m \u001b[38;5;241m100\u001b[39m,\n\u001b[0;32m      3\u001b[0m                   epochs \u001b[38;5;241m=\u001b[39m \u001b[38;5;241m25\u001b[39m,\n\u001b[0;32m      4\u001b[0m                   validation_data \u001b[38;5;241m=\u001b[39m test_,\n\u001b[0;32m      5\u001b[0m                   validation_steps \u001b[38;5;241m=\u001b[39m \u001b[38;5;241m50\u001b[39m)\n",
      "File \u001b[1;32m~\\AppData\\Local\\anaconda3\\envs\\YoloV8\\Lib\\site-packages\\keras\\src\\utils\\traceback_utils.py:122\u001b[0m, in \u001b[0;36mfilter_traceback.<locals>.error_handler\u001b[1;34m(*args, **kwargs)\u001b[0m\n\u001b[0;32m    119\u001b[0m     filtered_tb \u001b[38;5;241m=\u001b[39m _process_traceback_frames(e\u001b[38;5;241m.\u001b[39m__traceback__)\n\u001b[0;32m    120\u001b[0m     \u001b[38;5;66;03m# To get the full stack trace, call:\u001b[39;00m\n\u001b[0;32m    121\u001b[0m     \u001b[38;5;66;03m# `keras.config.disable_traceback_filtering()`\u001b[39;00m\n\u001b[1;32m--> 122\u001b[0m     \u001b[38;5;28;01mraise\u001b[39;00m e\u001b[38;5;241m.\u001b[39mwith_traceback(filtered_tb) \u001b[38;5;28;01mfrom\u001b[39;00m \u001b[38;5;28;01mNone\u001b[39;00m\n\u001b[0;32m    123\u001b[0m \u001b[38;5;28;01mfinally\u001b[39;00m:\n\u001b[0;32m    124\u001b[0m     \u001b[38;5;28;01mdel\u001b[39;00m filtered_tb\n",
      "File \u001b[1;32m~\\AppData\\Local\\anaconda3\\envs\\YoloV8\\Lib\\site-packages\\tensorflow\\python\\eager\\execute.py:53\u001b[0m, in \u001b[0;36mquick_execute\u001b[1;34m(op_name, num_outputs, inputs, attrs, ctx, name)\u001b[0m\n\u001b[0;32m     51\u001b[0m \u001b[38;5;28;01mtry\u001b[39;00m:\n\u001b[0;32m     52\u001b[0m   ctx\u001b[38;5;241m.\u001b[39mensure_initialized()\n\u001b[1;32m---> 53\u001b[0m   tensors \u001b[38;5;241m=\u001b[39m pywrap_tfe\u001b[38;5;241m.\u001b[39mTFE_Py_Execute(ctx\u001b[38;5;241m.\u001b[39m_handle, device_name, op_name,\n\u001b[0;32m     54\u001b[0m                                       inputs, attrs, num_outputs)\n\u001b[0;32m     55\u001b[0m \u001b[38;5;28;01mexcept\u001b[39;00m core\u001b[38;5;241m.\u001b[39m_NotOkStatusException \u001b[38;5;28;01mas\u001b[39;00m e:\n\u001b[0;32m     56\u001b[0m   \u001b[38;5;28;01mif\u001b[39;00m name \u001b[38;5;129;01mis\u001b[39;00m \u001b[38;5;129;01mnot\u001b[39;00m \u001b[38;5;28;01mNone\u001b[39;00m:\n",
      "\u001b[1;31mUnknownError\u001b[0m: Graph execution error:\n\nDetected at node PyFunc defined at (most recent call last):\n<stack traces unavailable>\nOSError: image file is truncated (37 bytes not processed)\nTraceback (most recent call last):\n\n  File \"C:\\Users\\alpnn\\AppData\\Local\\anaconda3\\envs\\YoloV8\\Lib\\site-packages\\tensorflow\\python\\ops\\script_ops.py\", line 270, in __call__\n    ret = func(*args)\n          ^^^^^^^^^^^\n\n  File \"C:\\Users\\alpnn\\AppData\\Local\\anaconda3\\envs\\YoloV8\\Lib\\site-packages\\tensorflow\\python\\autograph\\impl\\api.py\", line 643, in wrapper\n    return func(*args, **kwargs)\n           ^^^^^^^^^^^^^^^^^^^^^\n\n  File \"C:\\Users\\alpnn\\AppData\\Local\\anaconda3\\envs\\YoloV8\\Lib\\site-packages\\tensorflow\\python\\data\\ops\\from_generator_op.py\", line 198, in generator_py_func\n    values = next(generator_state.get_iterator(iterator_id))\n             ^^^^^^^^^^^^^^^^^^^^^^^^^^^^^^^^^^^^^^^^^^^^^^^\n\n  File \"C:\\Users\\alpnn\\AppData\\Local\\anaconda3\\envs\\YoloV8\\Lib\\site-packages\\keras\\src\\trainers\\data_adapters\\py_dataset_adapter.py\", line 250, in _get_iterator\n    for i, batch in enumerate(gen_fn()):\n\n  File \"C:\\Users\\alpnn\\AppData\\Local\\anaconda3\\envs\\YoloV8\\Lib\\site-packages\\keras\\src\\trainers\\data_adapters\\py_dataset_adapter.py\", line 244, in generator_fn\n    yield self.py_dataset[i]\n          ~~~~~~~~~~~~~~~^^^\n\n  File \"C:\\Users\\alpnn\\AppData\\Local\\anaconda3\\envs\\YoloV8\\Lib\\site-packages\\keras\\src\\legacy\\preprocessing\\image.py\", line 68, in __getitem__\n    return self._get_batches_of_transformed_samples(index_array)\n           ^^^^^^^^^^^^^^^^^^^^^^^^^^^^^^^^^^^^^^^^^^^^^^^^^^^^^\n\n  File \"C:\\Users\\alpnn\\AppData\\Local\\anaconda3\\envs\\YoloV8\\Lib\\site-packages\\keras\\src\\legacy\\preprocessing\\image.py\", line 313, in _get_batches_of_transformed_samples\n    img = image_utils.load_img(\n          ^^^^^^^^^^^^^^^^^^^^^\n\n  File \"C:\\Users\\alpnn\\AppData\\Local\\anaconda3\\envs\\YoloV8\\Lib\\site-packages\\keras\\src\\utils\\image_utils.py\", line 292, in load_img\n    img = img.resize(width_height_tuple, resample)\n          ^^^^^^^^^^^^^^^^^^^^^^^^^^^^^^^^^^^^^^^^\n\n  File \"C:\\Users\\alpnn\\AppData\\Local\\anaconda3\\envs\\YoloV8\\Lib\\site-packages\\PIL\\Image.py\", line 2156, in resize\n    self.load()\n\n  File \"C:\\Users\\alpnn\\AppData\\Local\\anaconda3\\envs\\YoloV8\\Lib\\site-packages\\PIL\\ImageFile.py\", line 266, in load\n    raise OSError(msg)\n\nOSError: image file is truncated (37 bytes not processed)\n\n\n\t [[{{node PyFunc}}]]\n\t [[IteratorGetNext]] [Op:__inference_one_step_on_iterator_2588]"
     ]
    }
   ],
   "source": [
    "egitim = model.fit(train_,\n",
    "                  steps_per_epoch = 100,\n",
    "                  epochs = 25,\n",
    "                  validation_data = test_,\n",
    "                  validation_steps = 50)"
   ]
  },
  {
   "cell_type": "code",
   "execution_count": null,
   "id": "136150db",
   "metadata": {},
   "outputs": [],
   "source": []
  }
 ],
 "metadata": {
  "kernelspec": {
   "display_name": "Python 3 (ipykernel)",
   "language": "python",
   "name": "python3"
  },
  "language_info": {
   "codemirror_mode": {
    "name": "ipython",
    "version": 3
   },
   "file_extension": ".py",
   "mimetype": "text/x-python",
   "name": "python",
   "nbconvert_exporter": "python",
   "pygments_lexer": "ipython3",
   "version": "3.11.5"
  }
 },
 "nbformat": 4,
 "nbformat_minor": 5
}
